Workbook

Sheet 요약
A1: Sport 예약 메이트 테스트 케이스
A2: 근거 문서: Sport 예약 메이트 테스트 수행 보고서 (2026-10-10), TestCase.xlsx
A4: 구분 | B4: 전체 | C4: Pass | D4: Fail | E4: 미수행 | F4: Blocked | G4: 수행률 | J4: 접두어 | K4: 영문 | L4: 대상 영역 | M4: 범위 | N4: 개수
A5: 부하 | B5: =COUNTIF('테스트 케이스'!$B$2:$B$66,A5) -> 9 | C5: =COUNTIFS('테스트 케이스'!$B$2:$B$66,$A5,'테스트 케이스'!$K$2:$K$66,"Pass") -> 3 | D5: =COUNTIFS('테스트 케이스'!$B$2:$B$66,$A5,'테스트 케이스'!$K$2:$K$66,"Fail") -> 6 | E5: =COUNTIFS('테스트 케이스'!$B$2:$B$66,$A5,'테스트 케이스'!$K$2:$K$66,"미수행") -> 0 | F5: =COUNTIFS('테스트 케이스'!$B$2:$B$66,$A5,'테스트 케이스'!$K$2:$K$66,"Blocked") -> 0 | G5: =IF(B5=0,0,(C5+D5+F5)/B5) -> 1 | J5: PF | K5: Perfomance | L5: 부하 · 성능 | M5: k6로 측정한 로그인 페이지 동시 접속, 이용권 대량 등록 응답 시간과 실패율 | N5: 9
A6: 배치 | B6: =COUNTIF('테스트 케이스'!$B$2:$B$66,A6) -> 15 | C6: =COUNTIFS('테스트 케이스'!$B$2:$B$66,$A6,'테스트 케이스'!$K$2:$K$66,"Pass") -> 13 | D6: =COUNTIFS('테스트 케이스'!$B$2:$B$66,$A6,'테스트 케이스'!$K$2:$K$66,"Fail") -> 2 | E6: =COUNTIFS('테스트 케이스'!$B$2:$B$66,$A6,'테스트 케이스'!$K$2:$K$66,"미수행") -> 0 | F6: =COUNTIFS('테스트 케이스'!$B$2:$B$66,$A6,'테스트 케이스'!$K$2:$K$66,"Blocked") -> 0 | G6: =IF(B6=0,0,(C6+D6+F6)/B6) -> 1 | J6: BT | K6: Batch | L6: Spring Batch | M6: addPassesJob의 처리 시간, 증가 패턴, 처리 후 데이터 정합성, Job 재실행 | N6: 15
A7: 로그인 | B7: =COUNTIF('테스트 케이스'!$B$2:$B$66,A7) -> 12 | C7: =COUNTIFS('테스트 케이스'!$B$2:$B$66,$A7,'테스트 케이스'!$K$2:$K$66,"Pass") -> 12 | D7: =COUNTIFS('테스트 케이스'!$B$2:$B$66,$A7,'테스트 케이스'!$K$2:$K$66,"Fail") -> 0 | E7: =COUNTIFS('테스트 케이스'!$B$2:$B$66,$A7,'테스트 케이스'!$K$2:$K$66,"미수행") -> 0 | F7: =COUNTIFS('테스트 케이스'!$B$2:$B$66,$A7,'테스트 케이스'!$K$2:$K$66,"Blocked") -> 0 | G7: =IF(B7=0,0,(C7+D7+F7)/B7) -> 1 | J7: L | K7: Login | L7: 로그인 화면 | M7: 브라우저에서 수행하는 로그인 기능, 세션, 그룹 매핑 | N7: 12
A8: 로그인 API | B8: =COUNTIF('테스트 케이스'!$B$2:$B$66,A8) -> 4 | C8: =COUNTIFS('테스트 케이스'!$B$2:$B$66,$A8,'테스트 케이스'!$K$2:$K$66,"Pass") -> 4 | D8: =COUNTIFS('테스트 케이스'!$B$2:$B$66,$A8,'테스트 케이스'!$K$2:$K$66,"Fail") -> 0 | E8: =COUNTIFS('테스트 케이스'!$B$2:$B$66,$A8,'테스트 케이스'!$K$2:$K$66,"미수행") -> 0 | F8: =COUNTIFS('테스트 케이스'!$B$2:$B$66,$A8,'테스트 케이스'!$K$2:$K$66,"Blocked") -> 0 | G8: =IF(B8=0,0,(C8+D8+F8)/B8) -> 1 | J8: LA | K8: Login API | L8: 로그인 API | M8: 화면 없이 POST /login/action을 직접 호출해 상태 코드와 응답 본문 검증 | N8: 4
A9: 보안 | B9: =COUNTIF('테스트 케이스'!$B$2:$B$66,A9) -> 2 | C9: =COUNTIFS('테스트 케이스'!$B$2:$B$66,$A9,'테스트 케이스'!$K$2:$K$66,"Pass") -> 2 | D9: =COUNTIFS('테스트 케이스'!$B$2:$B$66,$A9,'테스트 케이스'!$K$2:$K$66,"Fail") -> 0 | E9: =COUNTIFS('테스트 케이스'!$B$2:$B$66,$A9,'테스트 케이스'!$K$2:$K$66,"미수행") -> 0 | F9: =COUNTIFS('테스트 케이스'!$B$2:$B$66,$A9,'테스트 케이스'!$K$2:$K$66,"Blocked") -> 0 | G9: =IF(B9=0,0,(C9+D9+F9)/B9) -> 1 | J9: SC | K9: Security | L9: 보안 | M9: 비밀번호 저장 형식, 민감 정보 노출 여부 | N9: 2
A10: 회원가입 | B10: =COUNTIF('테스트 케이스'!$B$2:$B$66,A10) -> 2 | C10: =COUNTIFS('테스트 케이스'!$B$2:$B$66,$A10,'테스트 케이스'!$K$2:$K$66,"Pass") -> 1 | D10: =COUNTIFS('테스트 케이스'!$B$2:$B$66,$A10,'테스트 케이스'!$K$2:$K$66,"Fail") -> 1 | E10: =COUNTIFS('테스트 케이스'!$B$2:$B$66,$A10,'테스트 케이스'!$K$2:$K$66,"미수행") -> 0 | F10: =COUNTIFS('테스트 케이스'!$B$2:$B$66,$A10,'테스트 케이스'!$K$2:$K$66,"Blocked") -> 0 | G10: =IF(B10=0,0,(C10+D10+F10)/B10) -> 1 | J10: JN | K10: Join | L10: 회원가입 | M10: 회원 가입과 POST /join/action 를 호출해 API 가입, 입력값 검증, 경계값 테스트 | N10: 14
A11: 회원가입 API | B11: =COUNTIF('테스트 케이스'!$B$2:$B$66,A11) -> 13 | C11: =COUNTIFS('테스트 케이스'!$B$2:$B$66,$A11,'테스트 케이스'!$K$2:$K$66,"Pass") -> 12 | D11: =COUNTIFS('테스트 케이스'!$B$2:$B$66,$A11,'테스트 케이스'!$K$2:$K$66,"Fail") -> 1 | E11: =COUNTIFS('테스트 케이스'!$B$2:$B$66,$A11,'테스트 케이스'!$K$2:$K$66,"미수행") -> 0 | F11: =COUNTIFS('테스트 케이스'!$B$2:$B$66,$A11,'테스트 케이스'!$K$2:$K$66,"Blocked") -> 0 | G11: =IF(B11=0,0,(C11+D11+F11)/B11) -> 1 | J11: AD | K11: Admin | L11: 관리자 | M11: 대시보드, 이용권 일괄 등록 화면, 관리자 로그인, 통계 | N11: 6
A12: 관리자 | B12: =COUNTIF('테스트 케이스'!$B$2:$B$66,A12) -> 6 | C12: =COUNTIFS('테스트 케이스'!$B$2:$B$66,$A12,'테스트 케이스'!$K$2:$K$66,"Pass") -> 6 | D12: =COUNTIFS('테스트 케이스'!$B$2:$B$66,$A12,'테스트 케이스'!$K$2:$K$66,"Fail") -> 0 | E12: =COUNTIFS('테스트 케이스'!$B$2:$B$66,$A12,'테스트 케이스'!$K$2:$K$66,"미수행") -> 0 | F12: =COUNTIFS('테스트 케이스'!$B$2:$B$66,$A12,'테스트 케이스'!$K$2:$K$66,"Blocked") -> 0 | G12: =IF(B12=0,0,(C12+D12+F12)/B12) -> 1 | J12: BK | K12: Booking | L12: 예약 | M12: 예약 시간 중복 차단, 동시 요청 처리 | N12: 2
A13: 예약 | B13: =COUNTIF('테스트 케이스'!$B$2:$B$66,A13) -> 2 | C13: =COUNTIFS('테스트 케이스'!$B$2:$B$66,$A13,'테스트 케이스'!$K$2:$K$66,"Pass") -> 0 | D13: =COUNTIFS('테스트 케이스'!$B$2:$B$66,$A13,'테스트 케이스'!$K$2:$K$66,"Fail") -> 0 | E13: =COUNTIFS('테스트 케이스'!$B$2:$B$66,$A13,'테스트 케이스'!$K$2:$K$66,"미수행") -> 0 | F13: =COUNTIFS('테스트 케이스'!$B$2:$B$66,$A13,'테스트 케이스'!$K$2:$K$66,"Blocked") -> 2 | G13: =IF(B13=0,0,(C13+D13+F13)/B13) -> 1
A14: 합계 | B14: =SUM(B5:B13) -> 65 | C14: =SUM(C5:C13) -> 53 | D14: =SUM(D5:D13) -> 10 | E14: =SUM(E5:E13) -> 0 | F14: =SUM(F5:F13) -> 2 | G14: =IF(B14=0,0,(C14+D14+F14)/B14) -> 1
A16: 결함별 케이스
A17: 결함 ID | B17: 케이스 수 | C17: Fail | D17: 내용 | J17: 접두어 | K17: 의미 | L17: 예
A18: DEF-001 | B18: =COUNTIF('테스트 케이스'!$L$2:$L$66,A18) -> 2 | C18: =COUNTIFS('테스트 케이스'!$L$2:$L$66,A18,'테스트 케이스'!$K$2:$K$66,"Fail") -> 0 | D18: 로그인 응답·Console에 비밀번호 원문 노출 (수정 완료) | J18: DEF | K18: 기능 · 보안 결함 | L18: DEF-001 비밀번호 원문 노출
A19: DEF-002 | B19: =COUNTIF('테스트 케이스'!$L$2:$L$66,A19) -> 2 | C19: =COUNTIFS('테스트 케이스'!$L$2:$L$66,A19,'테스트 케이스'!$K$2:$K$66,"Fail") -> 0 | D19: 빈 이름·이메일 검사 미동작 가능성 (후보) | J19: ET | K19: 탐색적 테스트로 발견함 항목 | L19: ET 대시보드 400
A20: DEF-003 | B20: =COUNTIF('테스트 케이스'!$L$2:$L$66,A20) -> 1 | C20: =COUNTIFS('테스트 케이스'!$L$2:$L$66,A20,'테스트 케이스'!$K$2:$K$66,"Fail") -> 1 | D20: BCrypt 72바이트 초과 부분 무시 가능성 (후보) | J20: PERF | K20: 성능 결함 | L20: PERF-001 배치 반복 조회 병목
A21: DEF-004 | B21: =COUNTIF('테스트 케이스'!$L$2:$L$66,A21) -> 1 | C21: =COUNTIFS('테스트 케이스'!$L$2:$L$66,A21,'테스트 케이스'!$K$2:$K$66,"Fail") -> 1 | D21: 가입 예외를 삼켜 저장 없이 200 응답 (미수정)
A22: ET | B22: =COUNTIF('테스트 케이스'!$L$2:$L$66,A22) -> 1 | C22: =COUNTIFS('테스트 케이스'!$L$2:$L$66,A22,'테스트 케이스'!$K$2:$K$66,"Fail") -> 0 | D22: /admin 파라미터 없이 접속 시 400 (수정 완료)
A23: PERF-001 | B23: =COUNTIF('테스트 케이스'!$L$2:$L$66,A23) -> 3 | C23: =COUNTIFS('테스트 케이스'!$L$2:$L$66,A23,'테스트 케이스'!$K$2:$K$66,"Fail") -> 2 | D23: 배치 반복 조회 병목, 건당 SELECT 2k+2회 (수정 완료)
A24: PERF-002 | B24: =COUNTIF('테스트 케이스'!$L$2:$L$66,A24) -> 1 | C24: =COUNTIFS('테스트 케이스'!$L$2:$L$66,A24,'테스트 케이스'!$K$2:$K$66,"Fail") -> 1 | D24: 이용권 일괄 등록 목록 페이징 없음 (미수정)
A26: 작성 기준
A27: • 판정: Pass / Fail / 미수행 / Blocked 중에서 선택합니다 (목록에서 고르기). 수행 후 '실제 결과'와 '판정'만 채우면 요약이 자동으로 갱신됩니다.
A28: • 수행률 = (Pass + Fail + Blocked) / 전체. 미수행 케이스는 보고서의 향후 과제와 코드 분석에서 도출했습니다.
A29: • PF-01~06의 판정 기준(실패율 0%)은 보고서에 목표치가 정해져 있지 않아 둔 임시 기준입니다. 목표 응답 시간·실패율이 정해지면 수정하세요.
A30: • BT 케이스의 판정 기준은 k6 timeout(300초) 안에 COMPLETED 응답 여부입니다. 증가 패턴은 BT-04, BT-09에서 따로 판정합니다.
A31: • PERF-001, PERF-002는 보고서의 결함 목록에 없던 ID로, 성능 문제를 추적하려고 새로 붙였습니다.
A32: • 결함 ID가 적힌 Pass 케이스는 해당 결함의 수정 확인(회귀) 케이스입니다.
A33: • 웹서버 (8080, 8081)는 실행 상태임을 가정합니다
A34: • 웹서버 실행 후 스키마는 자동으로 생성됩니다

Sheet 테스트 케이스
A1: TC ID | B1: 구분 | C1: 기능/시나리오 | D1: 테스트 유형 | E1: 우선순위 | F1: 사전 조건 | G1: 입력 데이터 | H1: 테스트 절차 | I1: 기대 결과 | J1: 실제 결과 | K1: 판정 | L1: 관련 결함 | M1: 수행 방법 | N1: 근거 | O1: 비고
A2: PF-01 | B2: 부하 | C2: 로그인 페이지 | D2: 성능 | E2: Medium | G2: VU 100, duration 10s | H2: 1. loadtest1.js의 vus 설정 2. 10초 동안 각 VU가 1초 간격으로 GET /login 요청 3. k6 결과의 latency와 실패율 기록 | I2: 응답 실패율 0% | J2: avg 12.31ms, max 44.46ms, 실패율 0.00% | K2: Pass | L2: - | M2: k6 (loadtest1.js) | N2: 보고서 2.1 | O2: 판정 기준은 임시 기준(실패율 0%). 한 PC에서 부하 생성기와 서버를 함께 실행
A3: PF-02 | B3: 부하 | C3: 로그인 페이지 | D3: 성능 | E3: Medium | G3: VU 200, duration 10s | H3: 1. loadtest1.js의 vus 설정 2. 10초 동안 각 VU가 1초 간격으로 GET /login 요청 3. k6 결과의 latency와 실패율 기록 | I3: 응답 실패율 0% | J3: avg 19.65ms, max 50.65ms, 실패율 4.45% | K3: Fail | L3: - | M3: k6 (loadtest1.js) | N3: 보고서 2.1 | O3: 한 PC에서 부하 생성기와 서버를 함께 실행해 자원 경합 포함
A4: PF-03 | B4: 부하 | C4: 로그인 페이지 | D4: 성능 | E4: Medium | G4: VU 500, duration 10s | H4: 1. loadtest1.js의 vus 설정 2. 10초 동안 각 VU가 1초 간격으로 GET /login 요청 3. k6 결과의 latency와 실패율 기록 | I4: 응답 실패율 0% | J4: avg 36.65ms, max 170.46ms, 실패율 7.12% | K4: Fail | L4: - | M4: k6 (loadtest1.js) | N4: 보고서 2.1 | O4: 한 PC에서 부하 생성기와 서버를 함께 실행해 자원 경합 포함
A5: PF-04 | B5: 부하 | C5: 로그인 페이지 | D5: 성능 | E5: Medium | G5: VU 1,000, duration 10s | H5: 1. loadtest1.js의 vus 설정 2. 10초 동안 각 VU가 1초 간격으로 GET /login 요청 3. k6 결과의 latency와 실패율 기록 | I5: 응답 실패율 0% | J5: avg 59.87ms, max 329.53ms, 실패율 7.95% | K5: Fail | L5: - | M5: k6 (loadtest1.js) | N5: 보고서 2.1 | O5: 한 PC에서 부하 생성기와 서버를 함께 실행해 자원 경합 포함
A6: PF-05 | B6: 부하 | C6: 로그인 페이지 | D6: 성능 | E6: Medium | G6: VU 5,000, duration 10s | H6: 1. loadtest1.js의 vus 설정 2. 10초 동안 각 VU가 1초 간격으로 GET /login 요청 3. k6 결과의 latency와 실패율 기록 | I6: 응답 실패율 0% | J6: avg 1.44s, max 2.23s, 실패율 16.28% | K6: Fail | L6: - | M6: k6 (loadtest1.js) | N6: 보고서 2.1 | O6: 한 PC에서 부하 생성기와 서버를 함께 실행해 자원 경합 포함
A7: PF-06 | B7: 부하 | C7: 로그인 페이지 | D7: 성능 | E7: High | G7: VU 10,000, duration 10s | H7: 1. loadtest1.js의 vus 설정 2. 10초 동안 각 VU가 1초 간격으로 GET /login 요청 3. k6 결과의 latency와 실패율 기록 | I7: 응답 실패율 0% | J7: avg 2.76s, max 3.73s, 실패율 47.84% | K7: Fail | L7: - | M7: k6 (loadtest1.js) | N7: 보고서 2.1 | O7: 한 PC에서 부하 생성기와 서버를 함께 실행해 자원 경합 포함
A8: PF-07 | B8: 부하 | C8: 이용권 일괄 등록 | D8: 성능 | E8: High | F8: 관리자 계정(Basic 인증) | G8: packageSeq=1, userId=A1000000, startedAt=2026-12-31 10:00 | H8: 1. loadtest2.js 실행 (VU 20, shared-iterations 10,000, maxDuration 10m, redirects: 0) 2. 302 응답 수 확인 3. SELECT status, COUNT(*) FROM bulk_pass GROUP BY status; | I8: 10,000건 모두 302 응답, 실패율 0%, bulk_pass READY 10,000건 (유실 없음) | J8: 10,000/10,000 완료 (1분 9.4초), 실패율 0%, READY 10,000건 | K8: Pass | L8: - | M8: k6 (loadtest2.js) + SQL | N8: 보고서 2.2 | O8: 1차 실행은 k6가 302를 따라가 목록 조회까지 측정 → redirects: 0으로 측정 대상 한정
A9: PF-08 | B9: 부하 | C9: 이용권 일괄 등록 | D9: 성능 | E9: Medium | G9: VU 20, iterations 100·200·400·10,000 | H9: 1. bulkinsert.js를 iterations 100 / 200 / 400 / 10,000으로 각각 실행 2. 평균 응답 시간과 실패율 기록 | I9: 건수와 무관하게 평균 응답 시간 유지, 실패율 0% | J9: avg 111.38 / 115.96 / 114.94 / 125.92ms, 실패율 모두 0% | K9: Pass | L9: - | M9: k6 (bulkinsert.js) | N9: 보고서 3.5
A10: PF-09 | B10: 부하 | C10: 이용권 일괄 등록 목록 | D10: 성능 | E10: Medium | F10: bulk_pass 수천 건 이상 적재 | G10: bulk_pass 10,000건 | H10: 1. bulk_pass를 대량 적재 2. GET /admin/bulk-pass 응답 시간 측정 | I10: 목록이 페이징되어 데이터 양과 무관하게 일정한 응답 시간 | J10: 페이징 없이 전체 목록을 조회·렌더링. 1차 등록 테스트에서 반복할수록 느려짐 관찰 | K10: Fail | L10: PERF-002 | M10: k6 + 코드 분석 | N10: 보고서 2.2, 6.2 | O10: 응답 시간 수치는 별도 측정 필요
A11: BT-01 | B11: 배치 | C11: [개선 전] addPassesJob 처리 시간 | D11: 성능 | E11: Medium | G11: bulk_pass 100건 (모두 userId A1000000) | H11: 1. bulkinsert.js로 bulk_pass를 N건 적재 2. batch.js로 POST /job/launcher (addPassesJob) 1회 호출 3. 응답 시간과 COMPLETED 포함 여부 확인 | I11: 300초(timeout) 안에 COMPLETED 응답 | J11: 17.01초 (170.1ms/건), 200 OK, COMPLETED | K11: Pass | L11: - | M11: k6 (bulkinsert.js, batch.js) | N11: 보고서 3.2, 3.5
A12: BT-02 | B12: 배치 | C12: [개선 전] addPassesJob 처리 시간 | D12: 성능 | E12: Medium | G12: bulk_pass 200건 (모두 userId A1000000) | H12: 1. bulkinsert.js로 bulk_pass를 N건 적재 2. batch.js로 POST /job/launcher (addPassesJob) 1회 호출 3. 응답 시간과 COMPLETED 포함 여부 확인 | I12: 300초(timeout) 안에 COMPLETED 응답 | J12: 99초 (495.0ms/건), 200 OK, COMPLETED | K12: Pass | L12: - | M12: k6 (bulkinsert.js, batch.js) | N12: 보고서 3.2, 3.5
A13: BT-03 | B13: 배치 | C13: [개선 전] addPassesJob 처리 시간 | D13: 성능 | E13: High | G13: bulk_pass 400건 (모두 userId A1000000) | H13: 1. bulkinsert.js로 bulk_pass를 N건 적재 2. batch.js로 POST /job/launcher (addPassesJob) 1회 호출 3. 응답 시간과 COMPLETED 포함 여부 확인 | I13: 300초(timeout) 안에 COMPLETED 응답 | J13: 300초 안에 응답 없음 (k6 timeout) | K13: Fail | L13: PERF-001 | M13: k6 (bulkinsert.js, batch.js) | N13: 보고서 3.2, 3.5
A14: BT-04 | B14: 배치 | C14: [개선 전] 처리 시간 증가 패턴 | D14: 성능 | E14: High | G14: 100건 → 200건 | H14: BT-01, BT-02의 소요 시간 비교 | I14: 건수가 2배가 되면 처리 시간도 약 2배 (선형 증가) | J14: 건수 2배에 시간 5.8배 (17.01초 → 99초). 건당 SELECT 2k+2회 반복 조회가 원인 | K14: Fail | L14: PERF-001 | M14: 측정값 비교 + 코드 분석 | N14: 보고서 3.2, 3.3 | O14: 1만 건 요구사항 처리 불가로 판단
A15: BT-05 | B15: 배치 | C15: [개선 후] addPassesJob 처리 시간 | D15: 성능 | E15: Medium | G15: bulk_pass 100건 (모두 userId A1000000) | H15: 1. bulkinsert.js로 bulk_pass를 N건 적재 2. batch.js로 POST /job/launcher (addPassesJob) 1회 호출 3. 응답 시간과 COMPLETED 포함 여부 확인 | I15: 300초(timeout) 안에 COMPLETED 응답 | J15: 161.48ms (1.61ms/건), 200 OK, COMPLETED | K15: Pass | L15: - | M15: k6 (bulkinsert.js, batch.js) | N15: 보고서 3.2, 3.5
A16: BT-06 | B16: 배치 | C16: [개선 후] addPassesJob 처리 시간 | D16: 성능 | E16: Medium | G16: bulk_pass 200건 (모두 userId A1000000) | H16: 1. bulkinsert.js로 bulk_pass를 N건 적재 2. batch.js로 POST /job/launcher (addPassesJob) 1회 호출 3. 응답 시간과 COMPLETED 포함 여부 확인 | I16: 300초(timeout) 안에 COMPLETED 응답 | J16: 278.15ms (1.39ms/건), 200 OK, COMPLETED | K16: Pass | L16: - | M16: k6 (bulkinsert.js, batch.js) | N16: 보고서 3.2, 3.5
A17: BT-07 | B17: 배치 | C17: [개선 후] addPassesJob 처리 시간 | D17: 성능 | E17: High | G17: bulk_pass 400건 (모두 userId A1000000) | H17: 1. bulkinsert.js로 bulk_pass를 N건 적재 2. batch.js로 POST /job/launcher (addPassesJob) 1회 호출 3. 응답 시간과 COMPLETED 포함 여부 확인 | I17: 300초(timeout) 안에 COMPLETED 응답 | J17: 467.71ms (1.17ms/건), 200 OK, COMPLETED | K17: Pass | L17: - | M17: k6 (bulkinsert.js, batch.js) | N17: 보고서 3.2, 3.5
A18: BT-08 | B18: 배치 | C18: [개선 후] addPassesJob 처리 시간 | D18: 성능 | E18: High | G18: bulk_pass 10,000건 (모두 userId A1000000) | H18: 1. bulkinsert.js로 bulk_pass를 N건 적재 2. batch.js로 POST /job/launcher (addPassesJob) 1회 호출 3. 응답 시간과 COMPLETED 포함 여부 확인 | I18: 300초(timeout) 안에 COMPLETED 응답 | J18: 11.39초 (1.14ms/건), 200 OK, COMPLETED | K18: Pass | L18: - | M18: k6 (bulkinsert.js, batch.js) | N18: 보고서 3.2, 3.5
A19: BT-09 | B19: 배치 | C19: [개선 후] 처리 시간 증가 패턴 | D19: 성능 | E19: High | G19: 400건 → 10,000건 | H19: BT-07, BT-08의 소요 시간 비교 | I19: 건수에 비례하는 선형 증가 | J19: 건수 25배에 시간 24.4배 (467.71ms → 11.39초) | K19: Pass | L19: PERF-001 | M19: 측정값 비교 | N19: 보고서 3.5, 3.6 | O19: PERF-001 수정 확인
A20: BT-10 | B20: 배치 | C20: bulk_pass 상태 변경 | D20: 데이터 정합성 | E20: High | G20: 처리 대상 N건 | H20: SELECT status, COUNT(*) FROM bulk_pass GROUP BY status; | I20: 처리 대상 N건이 모두 COMPLETED, READY 0건 | J20: N건 COMPLETED 확인 | K20: Pass | L20: - | M20: SQL | N20: 보고서 3.1
A21: BT-11 | B21: 배치 | C21: pass·booking 생성 수 | D21: 데이터 정합성 | E21: High | G21: 처리 대상 N건 | H21: 1. SELECT COUNT(*) FROM pass; 2. SELECT COUNT(*) FROM booking; | I21: pass N건, booking N건 생성 (개선 전과 동일한 동작) | J21: 각 N건 생성 확인 | K21: Pass | L21: - | M21: SQL | N21: 보고서 3.4
A22: BT-12 | B22: 배치 | C22: booking의 pass_seq 고유성 | D22: 데이터 정합성 | E22: High | G22: 처리 대상 N건 | H22: SELECT COUNT(DISTINCT pass_seq) FROM booking; | I22: 서로 다른 pass_seq가 N개 (booking마다 다른 이용권 연결) | J22: N개 확인 | K22: Pass | L22: - | M22: SQL | N22: 보고서 3.4
A23: BT-13 | B23: 배치 | C23: booking-pass 연결 정합성 | D23: 데이터 정합성 | E23: Medium | G23: 처리 대상 N건 | H23: SELECT COUNT(*) FROM booking b LEFT JOIN pass p ON b.pass_seq = p.pass_seq WHERE p.pass_seq IS NULL; | I23: 결과 0건 (모든 booking이 존재하는 pass에 연결) | J23: 연결되는 pass가 없는 booking 0건 | K23: Pass | L23: - | M23: Selenium + PyMySQL (test._batch.py) | N23: 보고서 3.4
A24: BT-14 | B24: 배치 | C24: 처리 대상 기간 경계 | D24: 경계값 | E24: Medium | G24: startedAt = 현재 − 1일 − 1분 / 현재 − 1일 + 1분 | H24: 1. 시작 일시가 (현재 − 1일) 직전·직후인 bulk_pass를 각각 READY로 등록 2. addPassesJob 실행 3. 각 행의 status 확인 | I24: 직후 행만 COMPLETED, 직전 행은 READY 유지 | J24: 경계 안쪽(어제+5분)COMPLETED, 바깥 쪽(어제-5분)READY 유지 | K24: Pass | L24: - | M24: Selenium + PyMySQL (test._batch.py) | N24: 보고서 3.1 (Job 처리 흐름)
A25: BT-15 | B25: 배치 | C25: 중단된 Job 재실행 | D25: 예외 처리 | E25: Low | F25: addPassesJob 실행 도중 배치 서버 강제 종료 | G25: - | H25: 1. 배치 서버 재시작 후 addPassesJob 재요청 2. 오류 확인 3. batch_job_execution, batch_step_execution의 미종료 기록을 FAILED로 정리 4. 다시 요청 | I25: 2단계에서 중복 실행이 거부되고, 기록 정리 후 정상 실행 | J25: JobExecutionAlreadyRunningException 발생, 기록 정리 후 COMPLETED | K25: Pass | L25: - | M25: k6 + SQL | N25: 보고서 3.7 | O25: Spring Batch의 중복 실행 방지 동작. 자동 복구 절차는 없음
A26: L-01 | B26: 로그인 | C26: 정상 로그인 | D26: 기능 | E26: High | G26: 올바른 아이디·비밀번호 | H26: 1. /login 접속 2. 아이디·비밀번호 입력 후 submit | I26: URL이 /passes로 변경, 세션 쿠키 존재 | J26: /passes로 이동 확인 | K26: Pass | L26: - | M26: Selenium (try_login_1.py) | N26: TestCase.xlsx | O26: 세션 쿠키 존재 여부는 미검증
A27: L-02 | B27: 로그인 | C27: 존재하지 않는 ID | D27: 네거티브 | E27: High | G27: 아이디 wrong5798 | H27: 1. /login 접속 2. 없는 아이디 입력 후 submit | I27: alert "존재하지 않는 ID입니다.", /login 유지 | J27: 기대 문구와 일치 | K27: Pass | L27: - | M27: Selenium (test_unknown_id_alert) | N27: 보고서 5.3
A28: L-03 | B28: 로그인 | C28: 틀린 비밀번호 | D28: 네거티브 | E28: High | G28: 비밀번호 wrong1234! | H28: 1. /login 접속 2. 올바른 아이디, 틀린 비밀번호 입력 후 submit | I28: alert "비밀번호가 일치하지 않습니다." | J28: 기대 문구와 일치 | K28: Pass | L28: - | M28: Selenium (test_wrong_password_alert) | N28: 보고서 5.3
A29: L-04 | B29: 로그인 | C29: 아이디·비밀번호 모두 빈 값 | D29: 네거티브 | E29: Medium | G29: 빈 값 / 빈 값 | H29: 1. /login 접속 2. 입력 후 제출 | I29: "존재하지 않는 ID입니다."로 예상 (실행해서 확인) | J29: "존재하지 않는 ID입니다" | K29: Pass | L29: - | M29: Selenium + PyMySQL (test_login_ui.py) | N29: TestCase.xlsx
A30: L-05 | B30: 로그인 | C30: 아이디만 입력, 비밀번호 빈 값 | D30: 네거티브 | E30: Medium | G30: 올바른 아이디 / 빈 값 | H30: 1. /login 접속 2. 입력 후 제출 | I30: "비밀번호가 일치하지 않습니다."로 예상 | J30: "비밀번호가 일치하지 않습니다" | K30: Pass | L30: - | M30: Selenium + PyMySQL (test_login_ui.py) | N30: TestCase.xlsx
A31: L-06 | B31: 로그인 | C31: 비밀번호 입력 후 Enter로 제출 | D31: 기능 | E31: Medium | G31: 올바른 아이디·비밀번호 | H31: 1. /login 접속 2. 입력 후 제출 | I31: URL이 /passes로 변경, 세션 쿠키 존재 | J31: Enter 제출로 /passes로 이동 | K31: Pass | L31: - | M31: Selenium + PyMySQL (test_login_ui.py) | N31: TestCase.xlsx
A32: L-07 | B32: 로그인 | C32: 로그아웃 후 /login으로 복귀 | D32: 기능 | E32: High | G32: 로그인 상태에서 /login/logout | H32: 1. /login 접속 2. 입력 후 제출 | I32: URL이 /login, 세션 만료 | J32: 로그아웃 후 /login로 이동, /passes 재접속 시 로그인 상태 아님 확인 | K32: Pass | L32: - | M32: Selenium + PyMySQL (test_login_ui.py) | N32: TestCase.xlsx
A33: L-08 | B33: 로그인 | C33: 아이디에 SQL 구문 입력 | D33: 보안 | E33: High | G33: ' OR '1'='1 | H33: 1. /login 접속 2. 입력 후 제출 | I33: 로그인 실패 (JPA 파라미터 바인딩으로 우회 안 됨) | J33: OR '1'='1 입력 시 "존재하지 않는 ID입니다"알림, 우회 불가 확인 | K33: Pass | L33: - | M33: Selenium + PyMySQL (test_login_ui.py) | N33: TestCase.xlsx
A34: L-09 | B34: 로그인 | C34: 대소문자만 다른 ID로 로그인 | D34: 탐색적 | E34: Medium | G34: 가입 ID의 대소문자 변경 | H34: 1. /login 접속 2. 입력 후 제출 | I34: 대소문자 구분없이 로그인 성공 | J34: 대문자 아이디로 로그인 성공 | K34: Pass | L34: - | M34: Selenium + PyMySQL (test_login_ui.py) | N34: TestCase.xlsx
A35: L-10 | B35: 로그인 | C35: 로그인 전후 세션 변경 | D35: 보안 | E35: Medium | G35: - | H35: 1. 로그인 전 JSESSIONID 확인 2. 로그인 3. JSESSIONID 다시 확인 | I35: 로그인 후 새 세션 ID 발급 | J35: 값이 바뀜 | K35: Pass | L35: - | M35: 수동 (개발자 도구) | N35: 보고서 4.4
A36: L-11 | B36: 로그인 | C36: 첫 로그인 시 기본 그룹 부여 | D36: 데이터 정합성 | E36: Medium | F36: 그룹 매핑이 없는 계정 | G36: - | H36: 1. 로그인 전 user_group_mapping 행 수 조회 2. 로그인 3. 다시 조회 | I36: 0행 → 1행 | J36: 0행 → 1행 | K36: Pass | L36: - | M36: 수동 + SQL | N36: 보고서 4.4
A37: L-12 | B37: 로그인 | C37: 재로그인 시 그룹 매핑 중복 | D37: 데이터 정합성 | E37: Medium | F37: L-11 수행 후 | G37: - | H37: 1. 로그아웃 후 다시 로그인 2. user_group_mapping 행 수 조회 | I37: 1행 유지 (중복 저장 없음) | J37: 1행 유지 | K37: Pass | L37: - | M37: 수동 + SQL | N37: 보고서 4.4
A38: LA-01 | B38: 로그인 API | C38: 정상 로그인 | D38: 기능 | E38: High | G38: {"userId": 정상, "password": 정상} | H38: POST /login/action (JSON) | I38: 200, 본문 {} | J38: 200, {} | K38: Pass | L38: - | M38: Selenium + PyMySQL (test_login_success_status) | N38: 보고서 5.4
A39: LA-02 | B39: 로그인 API | C39: 응답 본문 비밀번호 노출 | D39: 보안·회귀 | E39: High | G39: 정상 계정 | H39: POST /login/action 후 응답 본문에 비밀번호 원문이 있는지 확인 | I39: 응답 본문에 비밀번호 원문 없음 | J39: 본문 {}, 원문 없음 | K39: Pass | L39: DEF-001 | M39: Selenium + PyMySQL (test_login_response_has_no_password) | N39: 보고서 4.1, 5.4 | O39: 수정 전에는 {"password":..., "userId":...} 반환
A40: LA-03 | B40: 로그인 API | C40: 틀린 비밀번호 | D40: 네거티브 | E40: High | G40: 정상 아이디, 틀린 비밀번호 | H40: POST /login/action | I40: 400, {"msg":"비밀번호가 일치하지 않습니다."} | J40: 기대값과 일치 | K40: Pass | L40: - | M40: Selenium + PyMySQL (test_login_wrong_password) | N40: 보고서 5.4
...
